[2025-04-01T18:44:33.604+0000] {taskinstance.py:1956} INFO - Dependencies all met for dep_context=non-requeueable deps ti=<TaskInstance: run_dbt_models.dbt_run manual__2025-04-01T18:44:29.402185+00:00 [queued]>
[2025-04-01T18:44:33.616+0000] {taskinstance.py:1956} INFO - Dependencies all met for dep_context=requeueable deps ti=<TaskInstance: run_dbt_models.dbt_run manual__2025-04-01T18:44:29.402185+00:00 [queued]>
[2025-04-01T18:44:33.617+0000] {taskinstance.py:2170} INFO - Starting attempt 1 of 2
[2025-04-01T18:44:33.677+0000] {taskinstance.py:2191} INFO - Executing <Task(BashOperator): dbt_run> on 2025-04-01 18:44:29.402185+00:00
[2025-04-01T18:44:33.681+0000] {standard_task_runner.py:60} INFO - Started process 54 to run task
[2025-04-01T18:44:33.684+0000] {standard_task_runner.py:87} INFO - Running: ['airflow', 'tasks', 'run', 'run_dbt_models', 'dbt_run', 'manual__2025-04-01T18:44:29.402185+00:00', '--job-id', '17', '--raw', '--subdir', 'DAGS_FOLDER/dbt_run_dag.py', '--cfg-path', '/tmp/tmpmem4hj58']
[2025-04-01T18:44:33.686+0000] {standard_task_runner.py:88} INFO - Job 17: Subtask dbt_run
[2025-04-01T18:44:33.761+0000] {logging_mixin.py:188} WARNING - /home/airflow/.local/lib/python3.8/site-packages/airflow/settings.py:194 DeprecationWarning: The sql_alchemy_conn option in [core] has been moved to the sql_alchemy_conn option in [database] - the old setting has been used, but please update your config.
[2025-04-01T18:44:33.838+0000] {task_command.py:423} INFO - Running <TaskInstance: run_dbt_models.dbt_run manual__2025-04-01T18:44:29.402185+00:00 [running]> on host 418fd5302f71
[2025-04-01T18:44:34.008+0000] {taskinstance.py:2480} INFO - Exporting env vars: AIRFLOW_CTX_DAG_OWNER='bb' AIRFLOW_CTX_DAG_ID='run_dbt_models' AIRFLOW_CTX_TASK_ID='dbt_run' AIRFLOW_CTX_EXECUTION_DATE='2025-04-01T18:44:29.402185+00:00' AIRFLOW_CTX_TRY_NUMBER='1' AIRFLOW_CTX_DAG_RUN_ID='manual__2025-04-01T18:44:29.402185+00:00'
[2025-04-01T18:44:34.010+0000] {subprocess.py:63} INFO - Tmp dir root location: /tmp
[2025-04-01T18:44:34.011+0000] {subprocess.py:75} INFO - Running command: ['/usr/bin/bash', '-c', 'cd /opt/airflow/dbt/nyc_taxi_analytics && dbt run']
[2025-04-01T18:44:34.017+0000] {subprocess.py:86} INFO - Output:
[2025-04-01T18:44:35.610+0000] {subprocess.py:93} INFO - [0m18:44:35  Running with dbt=1.8.7
[2025-04-01T18:44:35.921+0000] {subprocess.py:93} INFO - [0m18:44:35  Registered adapter: postgres=1.8.2
[2025-04-01T18:44:36.113+0000] {subprocess.py:93} INFO - [0m18:44:36  Unable to do partial parsing because profile has changed
[2025-04-01T18:44:37.597+0000] {subprocess.py:93} INFO - [0m18:44:37  [[33mWARNING[0m]: Deprecated functionality
[2025-04-01T18:44:37.598+0000] {subprocess.py:93} INFO - The `tests` config has been renamed to `data_tests`. Please see
[2025-04-01T18:44:37.598+0000] {subprocess.py:93} INFO - https://docs.getdbt.com/docs/build/data-tests#new-data_tests-syntax for more
[2025-04-01T18:44:37.599+0000] {subprocess.py:93} INFO - information.
[2025-04-01T18:44:37.855+0000] {subprocess.py:93} INFO - [0m18:44:37  [[33mWARNING[0m]: Configuration paths exist in your dbt_project.yml file which do not apply to any resources.
[2025-04-01T18:44:37.856+0000] {subprocess.py:93} INFO - There are 1 unused configuration paths:
[2025-04-01T18:44:37.858+0000] {subprocess.py:93} INFO - - models.nyc_taxi_analytics.example
[2025-04-01T18:44:38.053+0000] {subprocess.py:93} INFO - [0m18:44:38  Found 5 models, 11 data tests, 423 macros
[2025-04-01T18:44:38.058+0000] {subprocess.py:93} INFO - [0m18:44:38
[2025-04-01T18:44:38.197+0000] {subprocess.py:93} INFO - [0m18:44:38  Concurrency: 1 threads (target='dev')
[2025-04-01T18:44:38.198+0000] {subprocess.py:93} INFO - [0m18:44:38
[2025-04-01T18:44:38.268+0000] {subprocess.py:93} INFO - [0m18:44:38  1 of 5 START sql view model public.stg_yellow_tripdata ......................... [RUN]
[2025-04-01T18:44:38.387+0000] {subprocess.py:93} INFO - [0m18:44:38  1 of 5 ERROR creating sql view model public.stg_yellow_tripdata ................ [[31mERROR[0m in 0.11s]
[2025-04-01T18:44:38.391+0000] {subprocess.py:93} INFO - [0m18:44:38  2 of 5 SKIP relation public.avg_trip_dist_by_payment ........................... [[33mSKIP[0m]
[2025-04-01T18:44:38.394+0000] {subprocess.py:93} INFO - [0m18:44:38  3 of 5 SKIP relation public.daily_trip_metrics ................................. [[33mSKIP[0m]
[2025-04-01T18:44:38.397+0000] {subprocess.py:93} INFO - [0m18:44:38  4 of 5 SKIP relation public.revenue_by_vendor .................................. [[33mSKIP[0m]
[2025-04-01T18:44:38.400+0000] {subprocess.py:93} INFO - [0m18:44:38  5 of 5 SKIP relation public.trip_by_weekday .................................... [[33mSKIP[0m]
[2025-04-01T18:44:38.419+0000] {subprocess.py:93} INFO - [0m18:44:38
[2025-04-01T18:44:38.422+0000] {subprocess.py:93} INFO - [0m18:44:38  Finished running 5 view models in 0 hours 0 minutes and 0.36 seconds (0.36s).
[2025-04-01T18:44:38.490+0000] {subprocess.py:93} INFO - [0m18:44:38
[2025-04-01T18:44:38.490+0000] {subprocess.py:93} INFO - [0m18:44:38  [31mCompleted with 1 error and 0 warnings:[0m
[2025-04-01T18:44:38.491+0000] {subprocess.py:93} INFO - [0m18:44:38
[2025-04-01T18:44:38.492+0000] {subprocess.py:93} INFO - [0m18:44:38    Database Error in model stg_yellow_tripdata (models/staging/stg_yellow_tripdata.sql)
[2025-04-01T18:44:38.495+0000] {subprocess.py:93} INFO -   relation "public.yellow_tripdata_2023_01" does not exist
[2025-04-01T18:44:38.497+0000] {subprocess.py:93} INFO -   LINE 28: FROM public.yellow_tripdata_2023_01
[2025-04-01T18:44:38.498+0000] {subprocess.py:93} INFO -                 ^
[2025-04-01T18:44:38.498+0000] {subprocess.py:93} INFO -   compiled code at target/run/nyc_taxi_analytics/models/staging/stg_yellow_tripdata.sql
[2025-04-01T18:44:38.498+0000] {subprocess.py:93} INFO - [0m18:44:38
[2025-04-01T18:44:38.498+0000] {subprocess.py:93} INFO - [0m18:44:38  Done. PASS=0 WARN=0 ERROR=1 SKIP=4 TOTAL=5
[2025-04-01T18:44:40.324+0000] {subprocess.py:97} INFO - Command exited with return code 1
[2025-04-01T18:44:40.346+0000] {taskinstance.py:2698} ERROR - Task failed with exception
Traceback (most recent call last):
  File "/home/airflow/.local/lib/python3.8/site-packages/airflow/models/taskinstance.py", line 433, in _execute_task
    result = execute_callable(context=context, **execute_callable_kwargs)
  File "/home/airflow/.local/lib/python3.8/site-packages/airflow/operators/bash.py", line 212, in execute
    raise AirflowException(
airflow.exceptions.AirflowException: Bash command failed. The command returned a non-zero exit code 1.
[2025-04-01T18:44:40.352+0000] {taskinstance.py:1138} INFO - Marking task as UP_FOR_RETRY. dag_id=run_dbt_models, task_id=dbt_run, execution_date=20250401T184429, start_date=20250401T184433, end_date=20250401T184440
[2025-04-01T18:44:40.414+0000] {standard_task_runner.py:107} ERROR - Failed to execute job 17 for task dbt_run (Bash command failed. The command returned a non-zero exit code 1.; 54)
[2025-04-01T18:44:40.454+0000] {local_task_job_runner.py:234} INFO - Task exited with return code 1
[2025-04-01T18:44:40.485+0000] {taskinstance.py:3280} INFO - 0 downstream tasks scheduled from follow-on schedule check
