[2025-04-04T08:49:29.227+0000] {taskinstance.py:1956} INFO - Dependencies all met for dep_context=non-requeueable deps ti=<TaskInstance: full_pipeline_dag.run_dbt_models manual__2025-04-04T08:16:15.521213+00:00 [queued]>
[2025-04-04T08:49:29.242+0000] {taskinstance.py:1956} INFO - Dependencies all met for dep_context=requeueable deps ti=<TaskInstance: full_pipeline_dag.run_dbt_models manual__2025-04-04T08:16:15.521213+00:00 [queued]>
[2025-04-04T08:49:29.243+0000] {taskinstance.py:2170} INFO - Starting attempt 1 of 1
[2025-04-04T08:49:29.280+0000] {taskinstance.py:2191} INFO - Executing <Task(BashOperator): run_dbt_models> on 2025-04-04 08:16:15.521213+00:00
[2025-04-04T08:49:29.284+0000] {standard_task_runner.py:60} INFO - Started process 2045 to run task
[2025-04-04T08:49:29.287+0000] {standard_task_runner.py:87} INFO - Running: ['airflow', 'tasks', 'run', 'full_pipeline_dag', 'run_dbt_models', 'manual__2025-04-04T08:16:15.521213+00:00', '--job-id', '279', '--raw', '--subdir', 'DAGS_FOLDER/full_pipeline_dag.py', '--cfg-path', '/tmp/tmp4r5qvt2q']
[2025-04-04T08:49:29.289+0000] {standard_task_runner.py:88} INFO - Job 279: Subtask run_dbt_models
[2025-04-04T08:49:29.334+0000] {logging_mixin.py:188} WARNING - /home/airflow/.local/lib/python3.8/site-packages/airflow/settings.py:194 DeprecationWarning: The sql_alchemy_conn option in [core] has been moved to the sql_alchemy_conn option in [database] - the old setting has been used, but please update your config.
[2025-04-04T08:49:29.387+0000] {task_command.py:423} INFO - Running <TaskInstance: full_pipeline_dag.run_dbt_models manual__2025-04-04T08:16:15.521213+00:00 [running]> on host 43987fe3142a
[2025-04-04T08:49:29.594+0000] {taskinstance.py:2480} INFO - Exporting env vars: AIRFLOW_CTX_DAG_OWNER='airflow' AIRFLOW_CTX_DAG_ID='full_pipeline_dag' AIRFLOW_CTX_TASK_ID='run_dbt_models' AIRFLOW_CTX_EXECUTION_DATE='2025-04-04T08:16:15.521213+00:00' AIRFLOW_CTX_TRY_NUMBER='1' AIRFLOW_CTX_DAG_RUN_ID='manual__2025-04-04T08:16:15.521213+00:00'
[2025-04-04T08:49:29.595+0000] {subprocess.py:63} INFO - Tmp dir root location: /tmp
[2025-04-04T08:49:29.597+0000] {subprocess.py:75} INFO - Running command: ['/usr/bin/bash', '-c', 'cd /dbt/nyc_taxi_analytics && dbt run']
[2025-04-04T08:49:29.605+0000] {subprocess.py:86} INFO - Output:
[2025-04-04T08:49:29.613+0000] {subprocess.py:93} INFO - /usr/bin/bash: line 1: dbt: command not found
[2025-04-04T08:49:29.614+0000] {subprocess.py:97} INFO - Command exited with return code 127
[2025-04-04T08:49:29.630+0000] {taskinstance.py:2698} ERROR - Task failed with exception
Traceback (most recent call last):
  File "/home/airflow/.local/lib/python3.8/site-packages/airflow/models/taskinstance.py", line 433, in _execute_task
    result = execute_callable(context=context, **execute_callable_kwargs)
  File "/home/airflow/.local/lib/python3.8/site-packages/airflow/operators/bash.py", line 212, in execute
    raise AirflowException(
airflow.exceptions.AirflowException: Bash command failed. The command returned a non-zero exit code 127.
[2025-04-04T08:49:29.753+0000] {taskinstance.py:1138} INFO - Marking task as FAILED. dag_id=full_pipeline_dag, task_id=run_dbt_models, execution_date=20250404T081615, start_date=20250404T084929, end_date=20250404T084929
[2025-04-04T08:49:29.921+0000] {standard_task_runner.py:107} ERROR - Failed to execute job 279 for task run_dbt_models (Bash command failed. The command returned a non-zero exit code 127.; 2045)
[2025-04-04T08:49:29.943+0000] {local_task_job_runner.py:234} INFO - Task exited with return code 1
[2025-04-04T08:49:29.982+0000] {taskinstance.py:3280} INFO - 0 downstream tasks scheduled from follow-on schedule check
