[2025-04-03T05:30:40.607+0000] {taskinstance.py:1956} INFO - Dependencies all met for dep_context=non-requeueable deps ti=<TaskInstance: full_pipeline_dag.upload_raw_to_minio manual__2025-04-03T05:29:07.705849+00:00 [queued]>
[2025-04-03T05:30:40.621+0000] {taskinstance.py:1956} INFO - Dependencies all met for dep_context=requeueable deps ti=<TaskInstance: full_pipeline_dag.upload_raw_to_minio manual__2025-04-03T05:29:07.705849+00:00 [queued]>
[2025-04-03T05:30:40.621+0000] {taskinstance.py:2170} INFO - Starting attempt 2 of 3
[2025-04-03T05:30:40.665+0000] {taskinstance.py:2191} INFO - Executing <Task(PythonOperator): upload_raw_to_minio> on 2025-04-03 05:29:07.705849+00:00
[2025-04-03T05:30:40.669+0000] {standard_task_runner.py:60} INFO - Started process 153 to run task
[2025-04-03T05:30:40.672+0000] {standard_task_runner.py:87} INFO - Running: ['airflow', 'tasks', 'run', 'full_pipeline_dag', 'upload_raw_to_minio', 'manual__2025-04-03T05:29:07.705849+00:00', '--job-id', '119', '--raw', '--subdir', 'DAGS_FOLDER/full_pipeline_dag.py', '--cfg-path', '/tmp/tmpn1v41kqp']
[2025-04-03T05:30:40.674+0000] {standard_task_runner.py:88} INFO - Job 119: Subtask upload_raw_to_minio
[2025-04-03T05:30:40.731+0000] {logging_mixin.py:188} WARNING - /home/airflow/.local/lib/python3.8/site-packages/airflow/settings.py:194 DeprecationWarning: The sql_alchemy_conn option in [core] has been moved to the sql_alchemy_conn option in [database] - the old setting has been used, but please update your config.
[2025-04-03T05:30:40.794+0000] {task_command.py:423} INFO - Running <TaskInstance: full_pipeline_dag.upload_raw_to_minio manual__2025-04-03T05:29:07.705849+00:00 [running]> on host f623d289e47b
[2025-04-03T05:30:40.921+0000] {taskinstance.py:2480} INFO - Exporting env vars: AIRFLOW_CTX_DAG_OWNER='airflow' AIRFLOW_CTX_DAG_ID='full_pipeline_dag' AIRFLOW_CTX_TASK_ID='upload_raw_to_minio' AIRFLOW_CTX_EXECUTION_DATE='2025-04-03T05:29:07.705849+00:00' AIRFLOW_CTX_TRY_NUMBER='2' AIRFLOW_CTX_DAG_RUN_ID='manual__2025-04-03T05:29:07.705849+00:00'
[2025-04-03T05:30:41.172+0000] {logging_mixin.py:188} INFO - ☁️ Uploading /opt/data/raw/yellow_tripdata_2023-01.parquet to s3://nyc-taxi/raw/yellow_tripdata_2023-01.parquet via S3Hook...
[2025-04-03T05:30:41.200+0000] {base.py:83} INFO - Using connection ID 'minio_conn' for task execution.
[2025-04-03T05:30:41.201+0000] {connection_wrapper.py:378} INFO - AWS Connection (conn_id='minio_conn', conn_type='aws') credentials retrieved from login and password.
[2025-04-03T05:30:41.202+0000] {logging_mixin.py:188} WARNING - <string>:9 AirflowProviderDeprecationWarning: extra['host'] is deprecated and will be removed in a future release. Please set extra['endpoint_url'] instead
[2025-04-03T05:30:41.514+0000] {taskinstance.py:2698} ERROR - Task failed with exception
Traceback (most recent call last):
  File "/home/airflow/.local/lib/python3.8/site-packages/boto3/s3/transfer.py", line 371, in upload_file
    future.result()
  File "/home/airflow/.local/lib/python3.8/site-packages/s3transfer/futures.py", line 103, in result
    return self._coordinator.result()
  File "/home/airflow/.local/lib/python3.8/site-packages/s3transfer/futures.py", line 266, in result
    raise self._exception
  File "/home/airflow/.local/lib/python3.8/site-packages/s3transfer/tasks.py", line 139, in __call__
    return self._execute_main(kwargs)
  File "/home/airflow/.local/lib/python3.8/site-packages/s3transfer/tasks.py", line 162, in _execute_main
    return_value = self._main(**kwargs)
  File "/home/airflow/.local/lib/python3.8/site-packages/s3transfer/tasks.py", line 348, in _main
    response = client.create_multipart_upload(
  File "/home/airflow/.local/lib/python3.8/site-packages/botocore/client.py", line 553, in _api_call
    return self._make_api_call(operation_name, kwargs)
  File "/home/airflow/.local/lib/python3.8/site-packages/botocore/client.py", line 1009, in _make_api_call
    raise error_class(parsed_response, operation_name)
botocore.errorfactory.NoSuchBucket: An error occurred (NoSuchBucket) when calling the CreateMultipartUpload operation: The specified bucket does not exist

During handling of the above exception, another exception occurred:

Traceback (most recent call last):
  File "/home/airflow/.local/lib/python3.8/site-packages/airflow/models/taskinstance.py", line 433, in _execute_task
    result = execute_callable(context=context, **execute_callable_kwargs)
  File "/home/airflow/.local/lib/python3.8/site-packages/airflow/operators/python.py", line 199, in execute
    return_value = self.execute_callable()
  File "/home/airflow/.local/lib/python3.8/site-packages/airflow/operators/python.py", line 216, in execute_callable
    return self.python_callable(*self.op_args, **self.op_kwargs)
  File "/opt/airflow/dags/full_pipeline_dag.py", line 37, in upload_data
    upload_tripdata_to_minio()
  File "/opt/pipeline/ingest/upload_to_minio.py", line 14, in upload_tripdata_to_minio
    hook.load_file(
  File "/home/airflow/.local/lib/python3.8/site-packages/airflow/providers/amazon/aws/hooks/s3.py", line 137, in wrapper
    return func(*bound_args.args, **bound_args.kwargs)
  File "/home/airflow/.local/lib/python3.8/site-packages/airflow/providers/amazon/aws/hooks/s3.py", line 91, in wrapper
    return func(*bound_args.args, **bound_args.kwargs)
  File "/home/airflow/.local/lib/python3.8/site-packages/airflow/providers/amazon/aws/hooks/s3.py", line 1090, in load_file
    client.upload_file(filename, bucket_name, key, ExtraArgs=extra_args, Config=self.transfer_config)
  File "/home/airflow/.local/lib/python3.8/site-packages/boto3/s3/inject.py", line 145, in upload_file
    return transfer.upload_file(
  File "/home/airflow/.local/lib/python3.8/site-packages/boto3/s3/transfer.py", line 377, in upload_file
    raise S3UploadFailedError(
boto3.exceptions.S3UploadFailedError: Failed to upload /opt/data/raw/yellow_tripdata_2023-01.parquet to nyc-taxi/raw/yellow_tripdata_2023-01.parquet: An error occurred (NoSuchBucket) when calling the CreateMultipartUpload operation: The specified bucket does not exist
[2025-04-03T05:30:41.557+0000] {taskinstance.py:1138} INFO - Marking task as UP_FOR_RETRY. dag_id=full_pipeline_dag, task_id=upload_raw_to_minio, execution_date=20250403T052907, start_date=20250403T053040, end_date=20250403T053041
[2025-04-03T05:30:41.613+0000] {standard_task_runner.py:107} ERROR - Failed to execute job 119 for task upload_raw_to_minio (Failed to upload /opt/data/raw/yellow_tripdata_2023-01.parquet to nyc-taxi/raw/yellow_tripdata_2023-01.parquet: An error occurred (NoSuchBucket) when calling the CreateMultipartUpload operation: The specified bucket does not exist; 153)
[2025-04-03T05:30:41.650+0000] {local_task_job_runner.py:234} INFO - Task exited with return code 1
[2025-04-03T05:30:41.689+0000] {taskinstance.py:3280} INFO - 0 downstream tasks scheduled from follow-on schedule check
