[2025-04-01T18:16:45.323+0000] {taskinstance.py:1956} INFO - Dependencies all met for dep_context=non-requeueable deps ti=<TaskInstance: run_dbt_models.dbt_run manual__2025-04-01T18:15:36.475893+00:00 [queued]>
[2025-04-01T18:16:45.363+0000] {taskinstance.py:1956} INFO - Dependencies all met for dep_context=requeueable deps ti=<TaskInstance: run_dbt_models.dbt_run manual__2025-04-01T18:15:36.475893+00:00 [queued]>
[2025-04-01T18:16:45.364+0000] {taskinstance.py:2170} INFO - Starting attempt 2 of 2
[2025-04-01T18:16:45.427+0000] {taskinstance.py:2191} INFO - Executing <Task(BashOperator): dbt_run> on 2025-04-01 18:15:36.475893+00:00
[2025-04-01T18:16:45.438+0000] {standard_task_runner.py:60} INFO - Started process 75 to run task
[2025-04-01T18:16:45.443+0000] {standard_task_runner.py:87} INFO - Running: ['airflow', 'tasks', 'run', 'run_dbt_models', 'dbt_run', 'manual__2025-04-01T18:15:36.475893+00:00', '--job-id', '9', '--raw', '--subdir', 'DAGS_FOLDER/dbt_run_dag.py', '--cfg-path', '/tmp/tmpbyeljgro']
[2025-04-01T18:16:45.445+0000] {standard_task_runner.py:88} INFO - Job 9: Subtask dbt_run
[2025-04-01T18:16:45.504+0000] {logging_mixin.py:188} WARNING - /home/airflow/.local/lib/python3.8/site-packages/airflow/settings.py:194 DeprecationWarning: The sql_alchemy_conn option in [core] has been moved to the sql_alchemy_conn option in [database] - the old setting has been used, but please update your config.
[2025-04-01T18:16:45.559+0000] {task_command.py:423} INFO - Running <TaskInstance: run_dbt_models.dbt_run manual__2025-04-01T18:15:36.475893+00:00 [running]> on host dd6df6faa4e6
[2025-04-01T18:16:45.826+0000] {taskinstance.py:2480} INFO - Exporting env vars: AIRFLOW_CTX_DAG_OWNER='bb' AIRFLOW_CTX_DAG_ID='run_dbt_models' AIRFLOW_CTX_TASK_ID='dbt_run' AIRFLOW_CTX_EXECUTION_DATE='2025-04-01T18:15:36.475893+00:00' AIRFLOW_CTX_TRY_NUMBER='2' AIRFLOW_CTX_DAG_RUN_ID='manual__2025-04-01T18:15:36.475893+00:00'
[2025-04-01T18:16:45.827+0000] {subprocess.py:63} INFO - Tmp dir root location: /tmp
[2025-04-01T18:16:45.828+0000] {subprocess.py:75} INFO - Running command: ['/usr/bin/bash', '-c', 'cd /opt/airflow/dbt/nyc_taxi_analytics && dbt run']
[2025-04-01T18:16:45.846+0000] {subprocess.py:86} INFO - Output:
[2025-04-01T18:16:45.856+0000] {subprocess.py:93} INFO - /usr/bin/bash: line 1: dbt: command not found
[2025-04-01T18:16:45.857+0000] {subprocess.py:97} INFO - Command exited with return code 127
[2025-04-01T18:16:45.872+0000] {taskinstance.py:2698} ERROR - Task failed with exception
Traceback (most recent call last):
  File "/home/airflow/.local/lib/python3.8/site-packages/airflow/models/taskinstance.py", line 433, in _execute_task
    result = execute_callable(context=context, **execute_callable_kwargs)
  File "/home/airflow/.local/lib/python3.8/site-packages/airflow/operators/bash.py", line 212, in execute
    raise AirflowException(
airflow.exceptions.AirflowException: Bash command failed. The command returned a non-zero exit code 127.
[2025-04-01T18:16:45.876+0000] {taskinstance.py:1138} INFO - Marking task as FAILED. dag_id=run_dbt_models, task_id=dbt_run, execution_date=20250401T181536, start_date=20250401T181645, end_date=20250401T181645
[2025-04-01T18:16:45.914+0000] {standard_task_runner.py:107} ERROR - Failed to execute job 9 for task dbt_run (Bash command failed. The command returned a non-zero exit code 127.; 75)
[2025-04-01T18:16:45.938+0000] {local_task_job_runner.py:234} INFO - Task exited with return code 1
[2025-04-01T18:16:45.963+0000] {taskinstance.py:3280} INFO - 0 downstream tasks scheduled from follow-on schedule check
