[2025-04-01T18:38:42.608+0000] {taskinstance.py:1956} INFO - Dependencies all met for dep_context=non-requeueable deps ti=<TaskInstance: run_dbt_models.dbt_run manual__2025-04-01T18:38:38.675555+00:00 [queued]>
[2025-04-01T18:38:42.625+0000] {taskinstance.py:1956} INFO - Dependencies all met for dep_context=requeueable deps ti=<TaskInstance: run_dbt_models.dbt_run manual__2025-04-01T18:38:38.675555+00:00 [queued]>
[2025-04-01T18:38:42.626+0000] {taskinstance.py:2170} INFO - Starting attempt 1 of 2
[2025-04-01T18:38:42.673+0000] {taskinstance.py:2191} INFO - Executing <Task(BashOperator): dbt_run> on 2025-04-01 18:38:38.675555+00:00
[2025-04-01T18:38:42.677+0000] {standard_task_runner.py:60} INFO - Started process 56 to run task
[2025-04-01T18:38:42.681+0000] {standard_task_runner.py:87} INFO - Running: ['airflow', 'tasks', 'run', 'run_dbt_models', 'dbt_run', 'manual__2025-04-01T18:38:38.675555+00:00', '--job-id', '14', '--raw', '--subdir', 'DAGS_FOLDER/dbt_run_dag.py', '--cfg-path', '/tmp/tmpk215k1s7']
[2025-04-01T18:38:42.684+0000] {standard_task_runner.py:88} INFO - Job 14: Subtask dbt_run
[2025-04-01T18:38:42.731+0000] {logging_mixin.py:188} WARNING - /home/airflow/.local/lib/python3.8/site-packages/airflow/settings.py:194 DeprecationWarning: The sql_alchemy_conn option in [core] has been moved to the sql_alchemy_conn option in [database] - the old setting has been used, but please update your config.
[2025-04-01T18:38:42.795+0000] {task_command.py:423} INFO - Running <TaskInstance: run_dbt_models.dbt_run manual__2025-04-01T18:38:38.675555+00:00 [running]> on host 79c84511453b
[2025-04-01T18:38:42.994+0000] {taskinstance.py:2480} INFO - Exporting env vars: AIRFLOW_CTX_DAG_OWNER='bb' AIRFLOW_CTX_DAG_ID='run_dbt_models' AIRFLOW_CTX_TASK_ID='dbt_run' AIRFLOW_CTX_EXECUTION_DATE='2025-04-01T18:38:38.675555+00:00' AIRFLOW_CTX_TRY_NUMBER='1' AIRFLOW_CTX_DAG_RUN_ID='manual__2025-04-01T18:38:38.675555+00:00'
[2025-04-01T18:38:42.995+0000] {subprocess.py:63} INFO - Tmp dir root location: /tmp
[2025-04-01T18:38:42.996+0000] {subprocess.py:75} INFO - Running command: ['/usr/bin/bash', '-c', 'cd /opt/airflow/dbt/nyc_taxi_analytics && dbt run']
[2025-04-01T18:38:43.006+0000] {subprocess.py:86} INFO - Output:
[2025-04-01T18:38:44.967+0000] {subprocess.py:93} INFO - [0m18:38:44  Running with dbt=1.8.7
[2025-04-01T18:38:45.306+0000] {subprocess.py:93} INFO - [0m18:38:45  Registered adapter: postgres=1.8.2
[2025-04-01T18:38:45.496+0000] {subprocess.py:93} INFO - [0m18:38:45  Unable to do partial parsing because of a version mismatch
[2025-04-01T18:38:47.147+0000] {subprocess.py:93} INFO - [0m18:38:47  [[33mWARNING[0m]: Deprecated functionality
[2025-04-01T18:38:47.148+0000] {subprocess.py:93} INFO - The `tests` config has been renamed to `data_tests`. Please see
[2025-04-01T18:38:47.149+0000] {subprocess.py:93} INFO - https://docs.getdbt.com/docs/build/data-tests#new-data_tests-syntax for more
[2025-04-01T18:38:47.150+0000] {subprocess.py:93} INFO - information.
[2025-04-01T18:38:47.451+0000] {subprocess.py:93} INFO - [0m18:38:47  [[33mWARNING[0m]: Configuration paths exist in your dbt_project.yml file which do not apply to any resources.
[2025-04-01T18:38:47.452+0000] {subprocess.py:93} INFO - There are 1 unused configuration paths:
[2025-04-01T18:38:47.452+0000] {subprocess.py:93} INFO - - models.nyc_taxi_analytics.example
[2025-04-01T18:38:47.627+0000] {subprocess.py:93} INFO - [0m18:38:47  Found 5 models, 11 data tests, 423 macros
[2025-04-01T18:38:47.630+0000] {subprocess.py:93} INFO - [0m18:38:47
[2025-04-01T18:38:47.689+0000] {subprocess.py:93} INFO - [0m18:38:47
[2025-04-01T18:38:47.690+0000] {subprocess.py:93} INFO - [0m18:38:47  Finished running  in 0 hours 0 minutes and 0.06 seconds (0.06s).
[2025-04-01T18:38:47.691+0000] {subprocess.py:93} INFO - [0m18:38:47  Encountered an error:
[2025-04-01T18:38:47.692+0000] {subprocess.py:93} INFO - Database Error
[2025-04-01T18:38:47.692+0000] {subprocess.py:93} INFO -   connection to server at "localhost" (::1), port 5432 failed: Connection refused
[2025-04-01T18:38:47.693+0000] {subprocess.py:93} INFO -   	Is the server running on that host and accepting TCP/IP connections?
[2025-04-01T18:38:47.693+0000] {subprocess.py:93} INFO -   connection to server at "localhost" (127.0.0.1), port 5432 failed: Connection refused
[2025-04-01T18:38:47.694+0000] {subprocess.py:93} INFO -   	Is the server running on that host and accepting TCP/IP connections?
[2025-04-01T18:38:47.695+0000] {subprocess.py:93} INFO - 
[2025-04-01T18:38:49.204+0000] {subprocess.py:97} INFO - Command exited with return code 2
[2025-04-01T18:38:49.227+0000] {taskinstance.py:2698} ERROR - Task failed with exception
Traceback (most recent call last):
  File "/home/airflow/.local/lib/python3.8/site-packages/airflow/models/taskinstance.py", line 433, in _execute_task
    result = execute_callable(context=context, **execute_callable_kwargs)
  File "/home/airflow/.local/lib/python3.8/site-packages/airflow/operators/bash.py", line 212, in execute
    raise AirflowException(
airflow.exceptions.AirflowException: Bash command failed. The command returned a non-zero exit code 2.
[2025-04-01T18:38:49.232+0000] {taskinstance.py:1138} INFO - Marking task as UP_FOR_RETRY. dag_id=run_dbt_models, task_id=dbt_run, execution_date=20250401T183838, start_date=20250401T183842, end_date=20250401T183849
[2025-04-01T18:38:49.283+0000] {standard_task_runner.py:107} ERROR - Failed to execute job 14 for task dbt_run (Bash command failed. The command returned a non-zero exit code 2.; 56)
[2025-04-01T18:38:49.291+0000] {local_task_job_runner.py:234} INFO - Task exited with return code 1
[2025-04-01T18:38:49.322+0000] {taskinstance.py:3280} INFO - 0 downstream tasks scheduled from follow-on schedule check
